Workbook

Sheet Log
A1: Date | B1: What I did | C1: How it developed the skill | D1: Referral category | E1: Referral area | F1: Competency | G1: Macro skill | H1: Age band | I1: Week | J1: Paste-ready line
A2: Rows 2 to 85 below are your Roscommon days, already filled in from Appendix 4. You only need the dropdowns in D to H. Rows after that are blank for Cavan.
A3: 46056 | B3: NEPS induction day. IT set-up. Expenses and service protocol briefing. 10:00-16:00 | J3: Day 1 · NEPS Head Office, Dublin
A4: 46057 | B4: Shadowed supervisor: parent interview, pupil interview, WISC-V and WIAT-III administration observed, parent feedback meeting. Supervision 16:00-17:00 | J4: Day 2 · Lisacul NS
A5: 46058 | B5: PENDING — preparation and case reading. Social Inclusion team meeting 14:30-15:30 (Teams) | J5: Day P1 · Remote
A6: 46059 | B6: Shadowed supervisor day 2: WISC-V, WIAT-III, parent interview. Supervision 15:00-17:00 | J6: Day 3 · Lisacul NS
A7: 46062 | B7: Shadowed colleague: case file review, parent interview, formulation discussion. NEPS Continuum of Support reading | J7: Day 4 · St Coman's Wood PS
A8: 46063 | B8: Shadowed colleague: WISC-V, WIAT-III, parent interview. Social Inclusion meeting 14:00-15:00 | J8: Day 5 · Cloonakilla NS, Athlone
A9: 46064 | B9: Shadowed colleague: WISC-V, WIAT-III administration and scoring, parent interview | J9: Day 6 · Scoil Mhuire (Newtown NS)
A10: 46065 | B10: WISC-V manual study: index score structure, ethical considerations in test use | J10: Day 7 · Remote
A11: 46069 | B11: WISC-V script notes, standardised administration rules, subtest practice | J11: Day 8 · Remote
A12: 46070 | B12: Observed WISC-V and WIAT-III, dyslexia query (CS25-05909); parent, teacher and student consultations. Whole-staff ADHD input to school | J12: Day 9 · S.N. Pol Naofa (St Paul's BNS)
A13: 46071 | B13: WISC-V subtest study (school half term) | J13: Day 10 · Remote
A14: 46072 | B14: Social Inclusion team meeting 10:00-12:30 (Teams). WISC-V subtest study | J14: Day 11 · Remote
... A86: 46212 | B86: Supervision (Teams) 14:00-15:00. Placement closing documentation | J86: Day 78 · Remote
J87: =IF($A87="","",TEXT($A87,"DD/MM/YYYY")&" — "&$B87&IF($E87="",""," [Referral: "&$E87&"]")&IF($G87="",""," [Competency: "&$G87&"]")&IF($C87="",""," How it developed the skill: "&$C87))
J88: =IF($A88="","",TEXT($A88,"DD/MM/YYYY")&" — "&$B88&IF($E88="",""," [Referral: "&$E88&"]")&IF($G88="",""," [Competency: "&$G88&"]")&IF($C88="",""," How it developed the skill: "&$C88))
J89: =IF($A89="","",TEXT($A89,"DD/MM/YYYY")&" — "&$B89&IF($E89="",""," [Referral: "&$E89&"]")&IF($G89="",""," [Competency: "&$G89&"]")&IF($C89="",""," How it developed the skill: "&$C89))
J90: =IF($A90="","",TEXT($A90,"DD/MM/YYYY")&" — "&$B90&IF($E90="",""," [Referral: "&$E90&"]")&IF($G90="",""," [Competency: "&$G90&"]")&IF($C90="",""," How it developed the skill: "&$C90))
J91: =IF($A91="","",TEXT($A91,"DD/MM/YYYY")&" — "&$B91&IF($E91="",""," [Referral: "&$E91&"]")&IF($G91="",""," [Competency: "&$G91&"]")&IF($C91="",""," How it developed the skill: "&$C91))
J92: =IF($A92="","",TEXT($A92,"DD/MM/YYYY")&" — "&$B92&IF($E92="",""," [Referral: "&$E92&"]")&IF($G92="",""," [Competency: "&$G92&"]")&IF($C92="",""," How it developed the skill: "&$C92))
J93: =IF($A93="","",TEXT($A93,"DD/MM/YYYY")&" — "&$B93&IF($E93="",""," [Referral: "&$E93&"]")&IF($G93="",""," [Competency: "&$G93&"]")&IF($C93="",""," How it developed the skill: "&$C93))
J94: =IF($A94="","",TEXT($A94,"DD/MM/YYYY")&" — "&$B94&IF($E94="",""," [Referral: "&$E94&"]")&IF($G94="",""," [Competency: "&$G94&"]")&IF($C94="",""," How it developed the skill: "&$C94))
J95: =IF($A95="","",TEXT($A95,"DD/MM/YYYY")&" — "&$B95&IF($E95="",""," [Referral: "&$E95&"]")&IF($G95="",""," [Competency: "&$G95&"]")&IF($C95="",""," How it developed the skill: "&$C95))
J96: =IF($A96="","",TEXT($A96,"DD/MM/YYYY")&" — "&$B96&IF($E96="",""," [Referral: "&$E96&"]")&IF($G96="",""," [Competency: "&$G96&"]")&IF($C96="",""," How it developed the skill: "&$C96))
J97: =IF($A97="","",TEXT($A97,"DD/MM/YYYY")&" — "&$B97&IF($E97="",""," [Referral: "&$E97&"]")&IF($G97="",""," [Competency: "&$G97&"]")&IF($C97="",""," How it developed the skill: "&$C97))
J98: =IF($A98="","",TEXT($A98,"DD/MM/YYYY")&" — "&$B98&IF($E98="",""," [Referral: "&$E98&"]")&IF($G98="",""," [Competency: "&$G98&"]")&IF($C98="",""," How it developed the skill: "&$C98))
... J402: =IF($A402="","",TEXT($A402,"DD/MM/YYYY")&" — "&$B402&IF($E402="",""," [Referral: "&$E402&"]")&IF($G402="",""," [Competency: "&$G402&"]")&IF($C402="",""," How it developed the skill: "&$C402))

Sheet Reference
A1: Level | B1: UCD competency | C1: Blocks within it | D1: Macro skill | E1: Section | F1: Item | G1: Detail / why it matters | H1: Law and policy | I1: Where the evidence goes | J1: Time · phase · type | K1: Times logged | L1: Last logged | M1: 1 | N1: 2 | O1: 3 | P1: 4 | Q1: 5 | R1: 6 | S1: 7 | T1: 8 | U1: 9 | V1: 10 | W1: 11 | X1: 12 | Y1: 13 | Z1: 14 | AA1: 15 | AB1: 16 | AC1: 17 | AD1: 18 | AE1: 19 | AF1: 20 | AG1: IFF · Environmental | AH1: IFF · Biological | AI1: IFF · Cognitive | AJ1: IFF · Affective | AK1: IFF · Behavioural
A2: INDEX | B2: JUMP TO | E2: Click any line. Use the 1 / 2 / 3 buttons in the left margin to collapse and expand: 1 = headings only, 2 = skill names, 3 = everything.
C3: 1. Assessment | E3: 10 macro skills | F3: teaching written for 10 of 10
C4: 2. Formulation | E4: 6 macro skills | F4: teaching written for 6 of 6
C5: 3. Intervention | E5: 7 macro skills | F5: teaching written for 7 of 7
C6: 4. Systemic Change | E6: 6 macro skills | F6: teaching written for 6 of 6
C7: 5. Working with Others | E7: 6 macro skills | F7: teaching written for 6 of 6
C8: 6. Ethical Practice | E8: 7 macro skills | F8: teaching written for 7 of 7
C9: 7. Supervision | E9: 10 macro skills | F9: teaching written for 10 of 10
C10: 8. Research | E10: 3 macro skills | F10: teaching written for 3 of 3
C11: PART D — age band → category → what presents → who they go to → what you assess | F11: the four-level route
C12: PART E — the three-year route to PSI membership and CORU registration | F12: shows where you do NOT currently meet a requirement
C13: PART F — papers behind the tool choices | F13: found through Elicit, clickable
C14: PART G — tool by tool, taught | F14: before · administer · score · interpret · errors · read
C15: PART H — methods in full, everything on one row | F15: history · evidence · script · Q&A · why this over alternatives
C16: PART I — conditions explained at parent, teacher and child level | F16: misconceptions · analogies · Q&A · supervision · reflection
C17: PART J — what is complete and what is not | F17: the honest map, with priority order
C18: PART C — Interactive Factors prompt, in full, with Irish equivalents | F18: also columns N to R — scroll right
C19: PART B — all 102 CORU standards and 128 PSI clauses in full | F19: every standard number in Part A links here
A25: PART A | B25: BY COMPETENCY | E25: One row per section. Columns A–L hold the context; the numbered columns to the right hold that section's items, spread across. Scroll right.
A26: COMP | B26: 1. Assessment | E26: 10 macro skills · 17 referral areas
B27: 1. Assessment | E27: What CORU asks of this competency — verbatim | F27: 18 standards across this competency | M27: ▸ CORU 1.2 Be able to identify the limits of their practice and know when to seek advice and additional expertise or refer to another professional | N27: ▸ CORU 2.2 Be able to modify and adapt communication methods and styles, including verbal and non-verbal methods, to suit the individual service user, considering issues of language, age, culture, beliefs and health and/or social care needs | O27: ▸ CORU 2.8 Be able to produce clear, concise, accurate and objective documentation | P27: ▸ CORU 3.1 Be able to gather all appropriate background information relevant to the service user's health and social care needs | Q27: ▸ CORU 3.2 Be able to justify the selection of and implement appropriate assessment techniques and be able to undertake and record a thorough, sensitive and detailed assessment | R27: ▸ CORU 3.3 Be able to determine the appropriate tests/assessments required and undertake/arrange these tests | S27: ▸ CORU 3.4 Be able to analyse and critically evaluate the information collected in the assessment process | T27: ▸ CORU 5.2 Demonstrate a critical understanding of relevant biological sciences, human development, social and behavioural sciences and other related sciences, together with a knowledge of health and wellbeing | U27: ▸ CORU 5.6 Demonstrate safe and effective implementation of practical, technical and clinical/professional skills | V27: ▸ CORU 5.12 Know the psychological theories of education, human development, learning and teaching and their application in children, young people and adult learners | W27: ▸ CORU 5.13 Know the structures and systems of school, community and social settings in which educational, health and social care services are provided for children, young people and adult learners | X27: ▸ CORU 5.14 Know the impact of structures and systems in which educational services are provided on the development of children, young people and adult learners at individual, group and organisational levels | Y27: ▸ CORU 5.21 Establish, maintain and conclude a professional relationship with a service user, safely and ethically, recognising and managing professional boundaries | Z27: ▸ CORU 5.24 Identify and apply knowledge of the intersecting forms of diversity of service users, working in an inclusive, sensitive and equitable manner | AA27: ▸ CORU 5.27 Be able to produce clear, concise, accessible and accurate reports — devised in collaboration with service users, as appropriate — that are suitable for the intended audience and context of their use, in order to communicate and justify professional opinions made | AB27: ▸ CORU 5.28 Be able to critically evaluate the theory and application of a range of assessment methods used in educational psychology to identify psychological, educational and developmental needs at individual and group levels | AC27: ▸ CORU 5.31 Conduct a range of assessment methods safely and ethically, adapting and re-evaluating their application as appropriate | AD27: ▸ CORU 5.32 Interpret, synthesise and critically evaluate assessment data, within relevant conceptual frameworks, to inform case formulation and psychological intervention planning
B28: 1. Assessment | E28: What the PSI Code asks of this competency — verbatim | F28: 13 clauses across this competency | M28: ▸ PSI 1.1.1 Have sensible regard for individual clients' moral and cultural values. | N28: ▸ PSI 1.1.3 Convey respect for and abide by prevailing community mores, social customs, and cultural expectations in their scientific and professional activities. | O28: ▸ PSI 1.3.5 Ensure at least the following are understood: purpose and nature of the activity; mutual responsibilities; likely benefits and risks; alternatives; consequences of non-action; the option to refuse or withdraw at any time without prejudice; the period the consent applies to; and how to rescind consent. | P28: ▸ PSI 1.4.1 Seek as full and active participation as possible from others in decisions which affect them. | Q28: ▸ PSI 1.4.3 Respect the right of individuals to discontinue participation or service at any time, and be responsive to non-verbal indications of a desire to discontinue. | R28: ▸ PSI 2.2.2 Recognise the boundaries of their competence, and do not exceed these. | S28: ▸ PSI 2.3.1 Be mindful, when making decisions based on psychological data and techniques, of the limitations of such data and techniques. | T28: ▸ PSI 2.3.3 Terminate an activity when it is clear the activity is more harmful than beneficial, or when it is no longer needed. | U28: ▸ PSI 3.3.6 Take all reasonable steps to ensure tests and assessment methods are only used by those qualified and trained to do so. | V28: ▸ PSI 4.2.2 Take due care to avoid misrepresentation, exaggeration, distortion or errors in reporting assessment results, research findings or service effectiveness, and act quickly to correct any such error. | W28: ▸ PSI 4.2.5 Take care in communicating their knowledge, findings and views to clearly differentiate facts, opinions, theories, hypotheses and ideas. | X28: ▸ PSI 4.2.6 Not suppress disconfirming evidence of their findings and views, and acknowledge alternative hypotheses and explanations. | Y28: ▸ PSI 4.3.1 Respect the right of clients and research participants to receive an appropriate explanation of the nature, purpose and results of investigations, assessments and research findings, in language they can understand.
B29: 1. Assessment | E29: Three-year arc | F29: What good looks like each year | M29: Year 1 — You learn the instruments and administer them to standard. Accuracy is the whole task. A good Year 1 assessment is one where another psychologist could re-score your protocol and reach the same numbers. | N29: Year 2 — You choose the battery rather than administering the one you were given. Selection becomes the skill, and you start assessing in health settings where the referral questions differ. | O29: Year 3 — You assess in complex and high-risk contexts, build cross-battery approaches deliberately, and can justify not assessing at all.
F30: one skill = one row → | M30: 1 · CORU — number and focus | N30: 2 · PSI — number and focus | O30: 3 · Why this matters | P30: 4 · Teaching — how you build it | Q30: 5 · What to read | R30: 6 · Common errors that cost marks | S30: 7 · Rubric — grade 3, 4, 5 | T30: 8 · Blocks and micro-skills with pass tests | U30: 9 · Full chapter, where written | V30: 10 · Referral areas this skill serves | W30: 11 · Where the evidence goes | X30: 12 · Law and policy | Y30: 13 · Year and how it extends | Z30: 14 · — | AA30: 15 · — | AB30: 16 · — | AC30: 17 · — | AD30: 18 · — | AE30: 19 · — | AF30: 20 · —
A31: SKILL | B31: 1. Assessment | C31: ▸ Knowing the methods ▸ Entering a setting ▸ Knowing what to look at ▸ Turning observation into data | D31: 1. Observation in classroom, playground and clinic | E31: Macro skill | F31: 1. Observation in classroom, playground and clinic | G31: Everything about this skill is on this row. Scroll right. | K31: =COUNTIF(Log!$G$3:$G$402,"1. Observation in classroom, playground and clinic") | L31: =IF(COUNTIF(Log!$G$3:$G$402,"1. Observation in classroom, playground and clinic")=0,"",SUMPRODUCT(MAX((Log!$G$3:$G$402="1. Observation in classroom, playground and clinic")*Log!$A$3:$A$402))) | M31: ▸ CORU 2.8 Be able to produce clear, concise, accurate and objective documentation ▸ CORU 3.1 Be able to gather all appropriate background information relevant to the service user's health and social care needs ▸ CORU 5.31 Conduct a range of assessment methods safely and ethically, adapting and re-evaluating their application as appropriate | N31: ▸ PSI 1.1.1 Have sensible regard for individual clients' moral and cultural values. ▸ PSI 2.2.2 Recognise the boundaries of their competence, and do not exceed these. ▸ PSI 2.3.1 Be mindful, when making decisions based on psychological data and techniques, of the limitations of such data and techniques. ▸ PSI 4.2.5 Take care in communicating their knowledge, findings and views to clearly differentiate facts, opinions, theories, hypotheses and ideas. | O31: Observation is the only assessment method that shows you the child in the environment the referral is actually about. A WISC-V tells you about a child in a quiet room with one adult and no competing demands — which is not where the difficulty is happening. Everything a teacher describes is mediated through their interpretation; observation is your one chance at unmediated data. It is also the method most often done badly, because it looks like something anyone can do. | P31: ▸ The four methods and what each is for Narrative (running record) — you write continuous prose about what happens. Strength: captures sequence and context you did not anticipate. Weakness: you cannot quantify it, and your attention drifts to what is salient rather than what is frequent. Use it first, when you do not yet know what you are looking for. Timed interval sampling — you divide the observation into fixed intervals (commonly 15 or 30 seconds) and record whether the behaviour occurred in each. Strength: gives you a percentage you can compare before and after an intervention. Weakness: tells you nothing about why. Use it when you need a baseline. Event sampling (frequency count) — you count each occurrence of a defined behaviour. Strength: exact counts for discrete, countable behaviours. Weakness: useless for continuous states like off-task. Use it for hitting, calling out, leaving the seat. ABC recording — for each occurrence you record what came immediately before (antecedent), the behaviour, and what followed (consequence). Strength: the only one of the four that generates a hypothesis about function. Weakness: slow, and you will miss things while writing. Use it when the referral question is why. ▸ Why the method must be chosen before you go If you arrive without a method you will default to narrative, and narrative confirms whatever you already believed. Choosing beforehand forces you to operationalise the behaviour — to turn 'disruptive' into something you could count. That operationalisation is half the assessment. If you cannot define the behaviour tightly enough to record it, the referral question is not yet clear, and that is worth discovering before you spend an hour in a classroom. ▸ Reactivity, and what to do about it Your presence changes behaviour. Children perform, or freeze, or seek your attention. This is not a flaw to eliminate but a variable to report. Two practical moves: stay long enough that novelty wears off (the first ten minutes are usually unrepresentative), and observe on more than one occasion where possible. In the report, say what you think your presence did. A sentence such as 'Over the first ten minutes the pupil looked towards me repeatedly; this reduced thereafter and the data below are drawn from the remaining period' is more credible than pretending you were invisible. ▸ Looking at the environment, not only the child The referral names a child, but the data you need is relational. Count how many times the teacher directs an instruction at this child compared with a peer. Note where the child is seated and what they can see. Note the transition points — most difficulties cluster at transitions rather than during tasks. If you leave with data only about the child, you have produced a within-child account by default, and your formulation will follow it. | Q31: ▸ Sharp, P., Frederickson, N., & Cline, T. (2015). Educational psychology in practice: Observation. In Frederickson & Cline, Special educational needs, inclusion and diversity (3rd ed.). Open University Press. — the chapter on assessment methods. ▸ Department of Education and Skills (2017). Continuum of Support: Guidelines for teachers. NEPS. — read the section on classroom support, so you know what you are observing against. ▸ CORU (2023). Standards of proficiency for educational psychologists. Standards 3.1, 3.2, 5.31. | R31: ✗ Recording interpretation as description — 'he was frustrated' is an inference; 'he pushed the worksheet away and put his head down' is an observation. Write the second and infer later. ✗ Observing only the target child, and producing a within-child formulation by accident. ✗ Generalising from one lesson. One maths lesson on a Friday afternoon is not a profile. ✗ Not agreeing an introduction, so the child is singled out or told something untrue. ✗ Choosing narrative every time because it requires no preparation. | S31: ▸ GRADE 3 You recorded what happened accurately but could not say why you chose that method. ▸ GRADE 4 Method chosen and applied correctly; description and interpretation separated; context recorded alongside the child. ▸ GRADE 5 You can name what your method was blind to, you observed across settings, and your observation answers the referral question rather than describing everything. | T31: ▸ BLOCK 1 · Knowing the methods [3–4 hours, once · Weeks 1–2 · Study] The four observation methods — timed interval, event sampling, ABC recording, narrative — and what each is good and bad at. How you build it: Read one methods chapter. Write a one-page comparison. Then use each once. · Choose a method suited to the referral question you have it when: You can say why this one and what another would have missed [CORU SoP 3.2] · Run a timed interval or event sample accurately you have it when: Intervals are consistent and the record is legible to someone else [CORU SoP 5.6] · Record antecedent, behaviour and consequence separately you have it when: You have not written the cause into the description [CORU SoP 2.8] ▸ BLOCK 2 · Entering a setting [1 hour, then practice · Weeks 3–6 · Practice] How to be in a classroom without becoming the event — introduction, positioning, presence. How you build it: Ask your supervisor how they introduce themselves. Copy it until you have your own. · Agree with the teacher how you will be introduced you have it when: The child is told something true and is not singled out [CORU SoP 1.5 · PSI Code 1.1.1] · Position yourself to see without becoming the focus you have it when: The class settles within a few minutes [CORU SoP 5.31] · Observe without altering what you came to see you have it when: You can name how your presence may have changed things [PSI Code 2.3.1] ▸ BLOCK 3 · Knowing what to look at [Builds over 5–6 observations · Weeks 3–6 · Practice] The things worth noticing beyond the target behaviour — peer positioning, adult prompting, task demand, transitions. How you build it: Observe one child for the referral question, then observe the same lesson again for the context. The second is where the learning is. · Note peer interaction and social positioning you have it when: You can describe where this child sits in the peer group [CORU SoP 5.16] · Note adult interaction and prompting patterns you have it when: You have characterised the level of support given [CORU SoP 5.14] · Observe the same child across two settings you have it when: You have not generalised from one lesson [CORU SoP 3.1] ▸ BLOCK 4 · Turning observation into data [2–3 hours, then habit · Weeks 3–6 · Habit] Keeping description separate from interpretation, and linking what you saw to the question you were asked. How you build it: Write both sections separately for five observations. Have one checked. · Keep description and interpretation separate you have it when: Opinion is labelled as opinion throughout [CORU SoP 2.8 · PSI Code 4.2.5] · Link what you observed to the referral question you have it when: The observation answers something rather than describing everything [CORU SoP 3.4] | U31: ▸ Stage 1 · 0–25% What observation is actually for An observation answers a question that scores cannot. Scores tell you what a child can do under standardised, one-to-one, low-distraction conditions with an adult whose whole attention is on them. That is not a classroom. Observation tells you what the child does in the place where the difficulty was reported, which is almost always where the intervention will have to work. Description is not interpretation, and the whole discipline rests on keeping them apart. "Pushed the worksheet away" is description. "Was frustrated" is interpretation. "Avoids tasks he finds difficult" is a hypothesis. Write only the first in the observation record. The second belongs in the formulation, where you can be challenged on it. Trainees blur these constantly and it is the single most common reason an observation record is worthless to anyone else. Reactivity. Your presence changes the classroom. The teacher gives more directions, the target child either performs or freezes, the class watches you. This is not a flaw you can eliminate, only one you can reduce and report. Reduce it by staying longer than you need, sitting where you are not in sightlines, and agreeing a neutral introduction with the teacher beforehand. Report it by saying in the report that you observed for X minutes on one occasion and that your presence may have affected what you saw. What observation cannot tell you. It cannot tell you why. It can tell you what happens, how often, what comes before and after, and how this child compares to a peer in the same room. Causation requires either a functional analysis in which you manipulate conditions, or convergence with other evidence. A single observation is a snapshot with an n of one. ▸ Stage 2 · 25–50% Every method, and what each one is for There are seven methods you will actually use. Choosing between them before you enter the room is the skill; most trainees default to narrative because it requires no decision, and then find they have pages of prose that answer nothing. MethodWhat you doUse it whenWhat it cannot tell you Narrative / running recordWrite continuously in plain language, in sequence, with timestamps every few minutes.You do not yet know what the problem is. First observation of a new referral.Frequency, duration, or comparison. It is descriptive only and does not produce data. Event / frequency samplingTally each occurrence of a defined behaviour. Define it tightly first — "calls out without hand up" not "disruptive".The behaviour is discrete, countable, and has a clear start and end.How long each episode lasts, or what triggered it. Duration recordingTime each episode with a stopwatch, from a defined start to a defined end.How long matters more than how often — time off task, time to settle after transition.Frequency patterns, or context. Whole-interval recordingDivide the period into intervals (say 15 seconds). Mark only if the behaviour occurred for the entire interval.Continuous behaviours you want to be conservative about — on-task engagement.It systematically underestimates. Known bias; say so. Partial-interval recordingMark if the behaviour occurred at any point in the interval.Brief or high-frequency behaviours that are hard to count individually.It systematically overestimates. Known bias; say so. Momentary time samplingAt the end of each interval, look up and record whether the behaviour is occurring at that instant.You need an unbiased estimate of how much of the time something occurs, and you want to observe other things in between.Anything about individual episodes. But it is the least biased of the three interval methods and the one to prefer for engagement. ABC recordingThree columns. Antecedent, behaviour, consequence. Fill all three for every episode, in the moment.You are building a hypothesis about function.Function itself. ABC is descriptive functional assessment, not experimental. It generates a hypothesis; it does not confirm one. The comparison peer. An observation of a target child alone is nearly uninterpretable, because you have no idea what normal looks like in that room. Pick a same-sex peer of average attainment sitting in a comparable position, and record them on the same schedule. "Target child off task 60% of intervals" means nothing. "Target child off task 60%, comparison peer 25%" is a finding. ▸ Stage 3 · 50–75% Making it defensible Operational definitions. Before you observe, write down what counts. "Off task" must specify: not looking at the work, the teacher, or a peer who is helping, for more than three consecutive seconds. If you cannot write the definition, you cannot record the behaviour reliably, and neither can anyone else. Inter-observer agreement. The standard check is to have a second observer record simultaneously and compute agreement. Simple percentage agreement is agreements divided by agreements plus disagreements; Cohen's kappa corrects for chance agreement and is the better statistic. You will rarely get a second observer on placement. The honest response is to say so in the report rather than to imply a reliability you did not establish. Sampling adequacy. One twenty-minute observation in one lesson on one day is a very small sample of a child's week. Two settings minimum, and where you only have one, write in the report that one lesson is what you have. Vary time of day if you can — behaviour before lunch and after lunch are not the same behaviour. Scheduling. Choose the lesson where the difficulty was reported, not the lesson that is convenient. If the referral is about literacy, observing PE tells you something but not the thing you were asked. ▸ Stage 4 · 75–100% What experts know that the training does not say The psychometrics of classroom observation are weaker than practice assumes. Systematic direct observation has reasonable inter-observer reliability when definitions are tight, but temporal stability is poor — the same child observed on two different days can produce substantially different rates. Published work on observation of classroom behaviour has repeatedly found that a single session is an unreliable estimate of a child's typical behaviour, and that several sessions are needed for a stable estimate. Practising psychologists routinely report a single observation as though it were stable. Know that this is a compromise, and report the number of sessions. Observer expectancy. You read the referral before you observe. That referral tells you what to look for, and you will find it. This is not carelessness; it is a well-documented effect. Mitigations: define behaviours before reading the referral where possible; record the comparison peer on the same schedule so your bias applies equally to both; record descriptively and interpret afterwards rather than in the room. Descriptive versus experimental functional assessment. ABC recording is descriptive — you watch what naturally happens. Experimental functional analysis manipulates conditions systematically to test function. Descriptive methods agree with experimental methods less often than practitioners assume, particularly for behaviours maintained by automatic reinforcement. An ABC record supports a hypothesis; it does not establish a function. Write "consistent with" rather than "the function of this behaviour is". Structured protocols exist and are mostly better than what you will invent. The BOSS (Behavioral Observation of Students in Schools) uses momentary time sampling with a built-in peer comparison. The Student Behavior Teacher Response and similar coded systems capture the interaction rather than the child alone. Using a published protocol gives you a defined behaviour set and an evidence base; inventing your own each time gives you neither. When not to observe. If the referral question is about attainment rather than behaviour, observation adds little. If the child knows why you are there and is old enough to perform, the observation may be worse than useless. And if the teacher has already given you a clear behavioural account with frequencies, your observation may only confirm it at the cost of a morning. ▸ What to read SourceRead it for Sattler, J. M. (2018). Assessment of children: Cognitive foundations (6th ed.). Sattler Publisher.The observation chapter. The most practical single treatment of the methods. Frederickson, N., & Cline, T. (2015). Special educational needs, inclusion and diversity (3rd ed.). Open University Press.Observation within an ecological and interactive frame, written for UK/Irish EP practice. Shapiro, E. S. (2011). Academic skills problems workbook (4th ed.). Guilford.The BOSS protocol and how peer comparison is built into it. Hintze, J. M. (2005). Psychometrics of direct observation. School Psychology Review, 34(4), 507–519.The reliability and stability problem, stated directly. This is the stage-four reading. Thompson, R. H., & Iwata, B. A. (2007). A comparison of outcomes from descriptive and functional analyses of problem behavior. Journal of Applied Behavior Analysis, 40(2), 333–338.Why ABC and experimental functional analysis disagree. ▸ Copy and paste Click any block to copy it. Operational definition sheet Behaviour · Counts as · Does not count as · Minimum duration · Method · Interval · Comparison peer · Settings · Date ABC recording grid Time · Antecedent · Behaviour · Consequence, with the descriptive-only caveat built in Momentary time sampling grid, with peer comparison 20 intervals, target and comparison peer on the same schedule Observation write-up paragraph Method, definition, peer comparison, findings, and the limitations sentence that moves a report from a 3 to a 5 | V31: ▸ 1.1 Attention, concentration and work skills FULL ENTRY HERE ▸ 1.2 Language skills FULL ENTRY HERE ▸ 1.6 Co-ordination — fine motor / handwriting, gross motor / PE skills FULL ENTRY HERE ▸ 2.1 Behaviour in class FULL ENTRY HERE ▸ 2.2 Behaviour during break times and around the school FULL ENTRY HERE ▸ 4.1 Friendships and social skills full entry under 8. Social communication screening measures | W31: Table 2 area 1 · Appendix 5 tagged Assessment · Appendix 7 observation · Table 3 tools and categories | X31: Equal Status Acts 2000–2018 — reasonable accommodation · GDPR — lawful basis, minimisation | Y31: Year 1 — Extends to health and disability settings in Year 2.
A32: AREA | B32: 1. Assessment | D32: 1. Observation in classroom, playground and clinic | E32: Referral area | F32: 1.1 Attention, concentration and work skills | G32: ON THE FORM — Section 5 | K32: =COUNTIF(Log!$E$3:$E$402,"1.1 Attention, concentration and work skills") | L32: =IF(COUNTIF(Log!$E$3:$E$402,"1.1 Attention, concentration and work skills")=0,"",SUMPRODUCT(MAX((Log!$E$3:$E$402="1.1 Attention, concentration and work skills")*Log!$A$3:$A$402))) | M32: DIAGNOSES ▸ ADHD — combined presentation DSM-5-TR / ICD-11 6A05 ▸ ADHD — predominantly inattentive presentation DSM-5-TR / ICD-11 6A05 ▸ ADHD — predominantly hyperactive/impulsive presentation DSM-5-TR / ICD-11 6A05 ▸ Other specified ADHD DSM-5-TR / ICD-11 6A05 ▸ Unspecified ADHD DSM-5-TR / ICD-11 6A05 | N32: PRESENTATIONS WITH NO DIAGNOSIS ▸ Working memory difficulty Executive function profile, not a diagnosis ▸ Inhibition difficulty Executive function profile ▸ Cognitive flexibility difficulty Executive function profile ▸ Planning and organisation difficulty Executive function profile ▸ Task initiation difficulty Executive function profile ▸ Self-monitoring difficulty Executive function profile ▸ Motivation and engagement with work Added — not in the conditions index ▸ Work rate and pace of output Added ▸ Homework completion and follow-through Added ▸ Organisation of materials, books and equipment Added ▸ Sustained attention in whole-class vs one-to-one Added ▸ Note-taking and recording from the board Added ▸ Study skills and revision strategy Added ▸ Help-seeking — knowing when and how to ask Added ▸ Fatigue, sleep and time-of-day effects on attention Added | O32: REFER TO ▸ CAMHS (complex or medication) ▸ Primary Care ▸ CAMHS ▸ NEPS ▸ GP if persistent | P32: — | Q32: ▸ Early Years / Pre-School (0–5) Structured play observation · developmental history with parent · Preschool/AIM staff consultation · Conners EC (3–6) · no standardised cognitive attention measure at this age — describe, do not score. | R32: ▸ School Age (6–12) Classroom observation (momentary time sampling with a comparison peer) · Conners-4 parent and teacher · BRIEF-2 parent and teacher · WISC-V Working Memory and Processing Speed indices · TEA-Ch2 · work-sample analysis. | S32: ▸ Adolescent (13–16) Conners-4 including self-report · BRIEF-2 self-report · WISC-V or WAIS-IV depending on age · subject-teacher survey (Form 2 page 8) · study-skills and homework interview · RACE evidence if exam access is in question. | T32: ▸ Young Adult (17–26) WAIS-IV · BRIEF-A · self-report interview on study and workload · DSA/reasonable-accommodation evidence for third level · workplace or course demands analysis. | U32: ▸ Special Setting (class or school) Same tools, but interpret against the setting norm rather than the mainstream norm · staff consultation on the support already in place · check the referral question is about the pupil and not the placement. | AG32: Environmental Factors — Family, School, Community · Family dynamics (including CEC, adopted and CYP with SGOs) · Siblings, extended family, links and relationship to school and education · Family stressors · Financial stress · Housing · Home learning environment · Parental attitude to school/education · Trauma/significant life events · Adverse childhood events · Family views · Bereavements/relational losses · Key adults / members of staff (significant relationships both positive and negative in and out of school) and level of school commitment to child · Travel distance to school · School attendance · Child's views/preferences · School-parent relationship · Peer group dynamics · School learning environment · Access to interventions and support · Curriculum/exam boards · Teacher expectations · Teacher/staff understanding/knowledge · Attainment-based grouping · Influences in school and the local community · Other agency involvement — Police, YOT, CAMHS, Speech and Language Service, Fair Access, SENAT, Virtual School, SGO Advisor, Intensive Planning Team, Prevent, CSE, Early Years, School Nurse, Portage, Early Help, Social and Caring Services Health Services | AH32: Within-Child — Biological Factors · Family history including early development, physical development, medical conditions and diagnoses/difficulties · General health · Medication · Dietary needs · Sensory needs · Addictions e.g. smoking, drink, drugs | AI32: Within-Child — Cognitive Factors ASSESSABLE · Memory · Language · Executive functioning: including emotional and behavioural regulation/development · Attention and concentration · Visual spatial ability · Phonological processing · Processing speed · Non-verbal reasoning · Verbal ability (e.g. word problems, verbal presentation) · Logical reasoning ability · Literacy skills · Attainment OBSERVATION AND CONSULTATION · Signs of developmental trauma impacting on ability to participate in learning · Ability to problem-solve · Flexibility of thought and action · Self-awareness | AJ32: Within-Child — Affective Factors · Experience of developmental trauma · Confidence · Self-esteem · Emotional understanding and expression · Sense of enablement · Sense of self · Sense of belonging · Motivation (intrinsic or extrinsic) · Resiliency · Mood · Anxiety · Aspirations · Perseverance / determination · Sense of humour · Self-control · Social skills · Empathy | AK32: Within-Child — Behavioural Factors · Ability to develop and maintain friendships and relationships · Positive achievements · Care/concern for others, volunteering, helping · Dangerous or risk-taking behaviour · Verbal / physical abuse · Self-harm · Bullying · Truancy
A33: AREA | B33: 1. Assessment | D33: 1. Observation in classroom, playground and clinic | E33: Referral area | F33: 1.2 Language skills | G33: ON THE FORM — Section 5 | K33: =COUNTIF(Log!$E$3:$E$402,"1.2 Language skills") | L33: =IF(COUNTIF(Log!$E$3:$E$402,"1.2 Language skills")=0,"",SUMPRODUCT(MAX((Log!$E$3:$E$402="1.2 Language skills")*Log!$A$3:$A$402))) | M33: DIAGNOSES ▸ Language Disorder (expressive / receptive / mixed) — DLD DSM-5-TR / ICD-11 6A01 ▸ Speech Sound Disorder DSM-5-TR / ICD-11 6A01 ▸ Childhood-Onset Fluency Disorder (stuttering) DSM-5-TR / ICD-11 6A01 ▸ Unspecified Communication Disorder DSM-5-TR / ICD-11 6A01 ▸ Selective mutism DSM-5-TR anxiety / ICD-11 6B00–6B0Z | N33: PRESENTATIONS WITH NO DIAGNOSIS ▸ AAC and communication access Not a DSM diagnosis ▸ English as an Additional Language (EAL) Not a disorder — can mimic language disorder, rule out ▸ Bilingual language development Not a disorder ▸ Vocabulary gap from limited exposure Added ▸ Participation in oral work and classroom talk Added — Form 2 wording ▸ Following multi-step verbal instructions Added ▸ Narrative and sequencing in spoken account Added ▸ Word-finding difficulty Added ▸ Interpreter need and how it changes the assessment Added | O33: REFER TO ▸ NEPS with SLT ▸ NCSE speech and language class ▸ Primary Care (mild–moderate) ▸ CAMHS (severe) — also under 3.2 ▸ SLT ▸ CDNT ▸ NEPS ▸ NEPS interpreter request form | P33: — | Q33: ▸ Early Years / Pre-School (0–5) Preschool SLT report if any · parent developmental history (first words, phrases) · play-based language sample · Preschool Language Scales · always establish home language exposure before interpreting. | R33: ▸ School Age (6–12) BPVS-3 receptive vocabulary · EVT-3 expressive · CELF-5 via SLT · WISC-V Verbal Comprehension Index · classroom observation of oral participation · teacher report on instruction-following. | S33: ▸ Adolescent (13–16) CELF-5 (up to 21) via SLT · WISC-V/WAIS-IV VCI · subject-teacher survey on oral response · self-report on being understood · consider literacy consequences of unresolved DLD. | T33: ▸ Young Adult (17–26) WAIS-IV VCI · functional communication interview · course or workplace demands · self-advocacy for communication access. | U33: ▸ Special Setting (class or school) Language level of the setting itself · staff consultation on total communication approach · AAC in use and whether it is being used consistently. | AG33: Environmental Factors — Family, School, Community · Family dynamics (including CEC, adopted and CYP with SGOs) · Siblings, extended family, links and relationship to school and education · Family stressors · Financial stress · Housing · Home learning environment · Parental attitude to school/education · Trauma/significant life events · Adverse childhood events · Family views · Bereavements/relational losses · Key adults / members of staff (significant relationships both positive and negative in and out of school) and level of school commitment to child · Travel distance to school · School attendance · Child's views/preferences · School-parent relationship · Peer group dynamics · School learning environment · Access to interventions and support · Curriculum/exam boards · Teacher expectations · Teacher/staff understanding/knowledge · Attainment-based grouping · Influences in school and the local community · Other agency involvement — Police, YOT, CAMHS, Speech and Language Service, Fair Access, SENAT, Virtual School, SGO Advisor, Intensive Planning Team, Prevent, CSE, Early Years, School Nurse, Portage, Early Help, Social and Caring Services Health Services | AH33: Within-Child — Biological Factors · Family history including early development, physical development, medical conditions and diagnoses/difficulties · General health · Medication · Dietary needs · Sensory needs · Addictions e.g. smoking, drink, drugs | AI33: Within-Child — Cognitive Factors ASSESSABLE · Memory · Language · Executive functioning: including emotional and behavioural regulation/development · Attention and concentration · Visual spatial ability · Phonological processing · Processing speed · Non-verbal reasoning · Verbal ability (e.g. word problems, verbal presentation) · Logical reasoning ability · Literacy skills · Attainment OBSERVATION AND CONSULTATION · Signs of developmental trauma impacting on ability to participate in learning · Ability to problem-solve · Flexibility of thought and action · Self-awareness | AJ33: Within-Child — Affective Factors · Experience of developmental trauma · Confidence · Self-esteem · Emotional understanding and expression · Sense of enablement · Sense of self · Sense of belonging · Motivation (intrinsic or extrinsic) · Resiliency · Mood · Anxiety · Aspirations · Perseverance / determination · Sense of humour · Self-control · Social skills · Empathy | AK33: Within-Child — Behavioural Factors · Ability to develop and maintain friendships and relationships · Positive achievements · Care/concern for others, volunteering, helping · Dangerous or risk-taking behaviour · Verbal / physical abuse · Self-harm · Bullying · Truancy
A34: AREA | B34: 1. Assessment | D34: 1. Observation in classroom, playground and clinic | E34: Referral area | F34: 1.6 Co-ordination — fine motor / handwriting, gross motor / PE skills | G34: ON THE FORM — Section 5 | K34: =COUNTIF(Log!$E$3:$E$402,"1.6 Co-ordination — fine motor / handwriting, gross motor / PE skills") | L34: =IF(COUNTIF(Log!$E$3:$E$402,"1.6 Co-ordination — fine motor / handwriting, gross motor / PE skills")=0,"",SUMPRODUCT(MAX((Log!$E$3:$E$402="1.6 Co-ordination — fine motor / handwriting, gross motor / PE skills")*Log!$A$3:$A$402))) | M34: DIAGNOSES ▸ Developmental Coordination Disorder (dyspraxia) DSM-5-TR / ICD-11 6A04 ▸ Stereotypic Movement Disorder DSM-5-TR / ICD-11 6A04 ▸ Tourette's Disorder DSM-5-TR / ICD-11 Ch.08 ▸ Persistent (chronic) motor or vocal tic disorder DSM-5-TR / ICD-11 Ch.08 ▸ Provisional tic disorder DSM-5-TR / ICD-11 Ch.08 ▸ Other specified / unspecified tic disorder DSM-5-TR / ICD-11 Ch.08 ▸ Hypermobility spectrum disorder Medical | N34: PRESENTATIONS WITH NO DIAGNOSIS ▸ Fine motor difficulty (handwriting, pencil grip) Not a DSM diagnosis ▸ Gross motor difficulty (PE, balance, ball skills) Not a DSM diagnosis ▸ Sensory modulation difficulties (over- or under-responsive) Not a DSM diagnosis ▸ Sensory discrimination difficulties Not a DSM diagnosis ▸ Motor-based sensory difficulties Not a DSM diagnosis ▸ Presentation and care of written work Added — Form 2 wording ▸ Self-care and independence skills at school Added | O34: REFER TO ▸ CDNT / Occupational Therapy ▸ CDNT / OT ▸ CAMHS ▸ GP ▸ Paediatrics ▸ Occupational Therapy ▸ OT ▸ Physiotherapy ▸ NEPS | P34: — | Q34: ▸ Early Years / Pre-School (0–5) Movement ABC-2 (3+) · parent report on dressing, feeding, stairs · preschool observation · OT referral is usually the pathway, not NEPS assessment. | R34: ▸ School Age (6–12) DCD-Q parent questionnaire · Movement ABC-2 · Beery VMI · DASH handwriting speed · classroom observation of writing posture and grip · OT for diagnosis. | S34: ▸ Adolescent (13–16) DASH · Beery VMI · self-report on PE avoidance and social impact · RACE for handwriting (word processor, scribe) · practical-subject demands. | T34: ▸ Young Adult (17–26) DASH-17+ · functional and workplace demands · driving, laboratory or practical course requirements. | U34: ▸ Special Setting (class or school) Access to the physical environment · equipment and seating in place · OT recommendations already implemented or not. | AG34: Environmental Factors — Family, School, Community · Family dynamics (including CEC, adopted and CYP with SGOs) · Siblings, extended family, links and relationship to school and education · Family stressors · Financial stress · Housing · Home learning environment · Parental attitude to school/education · Trauma/significant life events · Adverse childhood events · Family views · Bereavements/relational losses · Key adults / members of staff (significant relationships both positive and negative in and out of school) and level of school commitment to child · Travel distance to school · School attendance · Child's views/preferences · School-parent relationship · Peer group dynamics · School learning environment · Access to interventions and support · Curriculum/exam boards · Teacher expectations · Teacher/staff understanding/knowledge · Attainment-based grouping · Influences in school and the local community · Other agency involvement — Police, YOT, CAMHS, Speech and Language Service, Fair Access, SENAT, Virtual School, SGO Advisor, Intensive Planning Team, Prevent, CSE, Early Years, School Nurse, Portage, Early Help, Social and Caring Services Health Services | AH34: Within-Child — Biological Factors · Family history including early development, physical development, medical conditions and diagnoses/difficulties · General health · Medication · Dietary needs · Sensory needs · Addictions e.g. smoking, drink, drugs | AI34: Within-Child — Cognitive Factors ASSESSABLE · Memory · Language · Executive functioning: including emotional and behavioural regulation/development · Attention and concentration · Visual spatial ability · Phonological processing · Processing speed · Non-verbal reasoning · Verbal ability (e.g. word problems, verbal presentation) · Logical reasoning ability · Literacy skills · Attainment OBSERVATION AND CONSULTATION · Signs of developmental trauma impacting on ability to participate in learning · Ability to problem-solve · Flexibility of thought and action · Self-awareness | AJ34: Within-Child — Affective Factors · Experience of developmental trauma · Confidence · Self-esteem · Emotional understanding and expression · Sense of enablement · Sense of self · Sense of belonging · Motivation (intrinsic or extrinsic) · Resiliency · Mood · Anxiety · Aspirations · Perseverance / determination · Sense of humour · Self-control · Social skills · Empathy | AK34: Within-Child — Behavioural Factors · Ability to develop and maintain friendships and relationships · Positive achievements · Care/concern for others, volunteering, helping · Dangerous or risk-taking behaviour · Verbal / physical abuse · Self-harm · Bullying · Truancy
A35: AREA | B35: 1. Assessment | D35: 1. Observation in classroom, playground and clinic | E35: Referral area | F35: 2.1 Behaviour in class | G35: ON THE FORM — Section 5 | K35: =COUNTIF(Log!$E$3:$E$402,"2.1 Behaviour in class") | L35: =IF(COUNTIF(Log!$E$3:$E$402,"2.1 Behaviour in class")=0,"",SUMPRODUCT(MAX((Log!$E$3:$E$402="2.1 Behaviour in class")*Log!$A$3:$A$402))) | M35: DIAGNOSES ▸ Oppositional Defiant Disorder — mild DSM-5-TR / ICD-11 6C90–6C9Z ▸ Oppositional Defiant Disorder — moderate DSM-5-TR / ICD-11 6C90–6C9Z ▸ Oppositional Defiant Disorder — severe DSM-5-TR / ICD-11 6C90–6C9Z ▸ Intermittent Explosive Disorder DSM-5-TR / ICD-11 6C70–6C7Z ▸ Disruptive Mood Dysregulation Disorder DSM-5-TR / ICD-11 6A70–6A7Z | N35: PRESENTATIONS WITH NO DIAGNOSIS ▸ Behaviour that challenges Not a DSM diagnosis ▸ Behaviour function (ABC analysis, trigger-behaviour-consequence) Formulation approach, not a diagnosis ▸ Emotion regulation in the classroom Added ▸ Response to correction and repair after an incident Added ▸ Transitions between activities and between classes Added ▸ Behaviour system fit — is the system working for this pupil Added ▸ Escalation and de-escalation pattern Added ▸ Behaviour as communication of an unmet learning need Added — always test this hypothesis | O35: REFER TO ▸ NEPS (school behaviour) ▸ CAMHS ▸ NEPS ▸ CAMHS (mod–severe) ▸ Primary Care (mild–mod) | P35: — | Q35: ▸ Early Years / Pre-School (0–5) ABC recording by preschool staff · structured observation · parent report on home/setting difference · SDQ (2–4 version) · behaviour at this age is usually developmental — frame it that way. | R35: ▸ School Age (6–12) ABC grid across a week · momentary time sampling with peer comparison · SDQ or BASC-3 (TRS and PRS) · functional behaviour assessment · Continuum of Support level check. | S35: ▸ Adolescent (13–16) BASC-3 including self-report · subject-teacher survey — is it all classes or some · pupil interview on their account of the incidents · school discipline record. | T35: ▸ Young Adult (17–26) Self-report and functional analysis · course or workplace conduct expectations · less likely to be a NEPS referral. | U35: ▸ Special Setting (class or school) Behaviour against the setting baseline · staff consistency · whether the environment is generating the behaviour. | AG35: Environmental Factors — Family, School, Community · Family dynamics (including CEC, adopted and CYP with SGOs) · Siblings, extended family, links and relationship to school and education · Family stressors · Financial stress · Housing · Home learning environment · Parental attitude to school/education · Trauma/significant life events · Adverse childhood events · Family views · Bereavements/relational losses · Key adults / members of staff (significant relationships both positive and negative in and out of school) and level of school commitment to child · Travel distance to school · School attendance · Child's views/preferences · School-parent relationship · Peer group dynamics · School learning environment · Access to interventions and support · Curriculum/exam boards · Teacher expectations · Teacher/staff understanding/knowledge · Attainment-based grouping · Influences in school and the local community · Other agency involvement — Police, YOT, CAMHS, Speech and Language Service, Fair Access, SENAT, Virtual School, SGO Advisor, Intensive Planning Team, Prevent, CSE, Early Years, School Nurse, Portage, Early Help, Social and Caring Services Health Services | AH35: Within-Child — Biological Factors · Family history including early development, physical development, medical conditions and diagnoses/difficulties · General health · Medication · Dietary needs · Sensory needs · Addictions e.g. smoking, drink, drugs | AI35: Within-Child — Cognitive Factors ASSESSABLE · Memory · Language · Executive functioning: including emotional and behavioural regulation/development · Attention and concentration · Visual spatial ability · Phonological processing · Processing speed · Non-verbal reasoning · Verbal ability (e.g. word problems, verbal presentation) · Logical reasoning ability · Literacy skills · Attainment OBSERVATION AND CONSULTATION · Signs of developmental trauma impacting on ability to participate in learning · Ability to problem-solve · Flexibility of thought and action · Self-awareness | AJ35: Within-Child — Affective Factors · Experience of developmental trauma · Confidence · Self-esteem · Emotional understanding and expression · Sense of enablement · Sense of self · Sense of belonging · Motivation (intrinsic or extrinsic) · Resiliency · Mood · Anxiety · Aspirations · Perseverance / determination · Sense of humour · Self-control · Social skills · Empathy | AK35: Within-Child — Behavioural Factors · Ability to develop and maintain friendships and relationships · Positive achievements · Care/concern for others, volunteering, helping · Dangerous or risk-taking behaviour · Verbal / physical abuse · Self-harm · Bullying · Truancy
A36: AREA | B36: 1. Assessment | D36: 1. Observation in classroom, playground and clinic | E36: Referral area | F36: 2.2 Behaviour during break times and around the school | G36: ON THE FORM — Section 5 | K36: =COUNTIF(Log!$E$3:$E$402,"2.2 Behaviour during break times and around the school") | L36: =IF(COUNTIF(Log!$E$3:$E$402,"2.2 Behaviour during break times and around the school")=0,"",SUMPRODUCT(MAX((Log!$E$3:$E$402="2.2 Behaviour during break times and around the school")*Log!$A$3:$A$402))) | M36: DIAGNOSES ▸ Conduct Disorder — childhood-onset type DSM-5-TR / ICD-11 6C90–6C9Z ▸ Conduct Disorder — adolescent-onset type DSM-5-TR / ICD-11 6C90–6C9Z ▸ Conduct Disorder — unspecified onset DSM-5-TR / ICD-11 6C90–6C9Z ▸ Pyromania DSM-5-TR / ICD-11 6C70–6C7Z ▸ Kleptomania DSM-5-TR / ICD-11 6C70–6C7Z ▸ Other specified / unspecified disruptive, impulse-control and conduct disorder DSM-5-TR ▸ Substance use disorders (alcohol, cannabis, opioid, stimulant, tobacco, inhalant, sedative, hallucinogen) DSM-5-TR / ICD-11 6C40–6C4Z ▸ Gambling Disorder DSM-5-TR / ICD-11 6C50–6C5Z ▸ Gaming Disorder / Internet Gaming Disorder ICD-11 6C51 | N36: PRESENTATIONS WITH NO DIAGNOSIS ▸ Harmful or sexualised behaviour in children Not a DSM diagnosis ▸ Adolescent substance misuse / dual diagnosis Not a standalone diagnosis ▸ Unstructured time — yard and corridor as the difficulty Added ▸ Supervision ratio and yard layout Added ▸ Group dynamics and peer influence Added ▸ Risk-taking without a diagnosis attached Added | O36: REFER TO ▸ NEPS ▸ CAMHS ▸ Addiction services ▸ Tusla | P36: — | Q36: ▸ Early Years / Pre-School (0–5) Yard observation · staff report · developmentally, most of this is not yet meaningful — describe rather than classify. | R36: ▸ School Age (6–12) Yard observation (event/frequency recording) · sociometric or friendship mapping · SDQ peer subscale · compare classroom vs yard — the difference is the finding. | S36: ▸ Adolescent (13–16) Corridor and break observation where possible · pupil interview · school incident record · substance screening is not NEPS work — refer. | T36: ▸ Young Adult (17–26) Not typically a NEPS referral at this band. | U36: ▸ Special Setting (class or school) Break-time structure in the setting · supported vs unsupported time · staffing at transitions. | AG36: Environmental Factors — Family, School, Community · Family dynamics (including CEC, adopted and CYP with SGOs) · Siblings, extended family, links and relationship to school and education · Family stressors · Financial stress · Housing · Home learning environment · Parental attitude to school/education · Trauma/significant life events · Adverse childhood events · Family views · Bereavements/relational losses · Key adults / members of staff (significant relationships both positive and negative in and out of school) and level of school commitment to child · Travel distance to school · School attendance · Child's views/preferences · School-parent relationship · Peer group dynamics · School learning environment · Access to interventions and support · Curriculum/exam boards · Teacher expectations · Teacher/staff understanding/knowledge · Attainment-based grouping · Influences in school and the local community · Other agency involvement — Police, YOT, CAMHS, Speech and Language Service, Fair Access, SENAT, Virtual School, SGO Advisor, Intensive Planning Team, Prevent, CSE, Early Years, School Nurse, Portage, Early Help, Social and Caring Services Health Services | AH36: Within-Child — Biological Factors · Family history including early development, physical development, medical conditions and diagnoses/difficulties · General health · Medication · Dietary needs · Sensory needs · Addictions e.g. smoking, drink, drugs | AI36: Within-Child — Cognitive Factors ASSESSABLE · Memory · Language · Executive functioning: including emotional and behavioural regulation/development · Attention and concentration · Visual spatial ability · Phonological processing · Processing speed · Non-verbal reasoning · Verbal ability (e.g. word problems, verbal presentation) · Logical reasoning ability · Literacy skills · Attainment OBSERVATION AND CONSULTATION · Signs of developmental trauma impacting on ability to participate in learning · Ability to problem-solve · Flexibility of thought and action · Self-awareness | AJ36: Within-Child — Affective Factors · Experience of developmental trauma · Confidence · Self-esteem · Emotional understanding and expression · Sense of enablement · Sense of self · Sense of belonging · Motivation (intrinsic or extrinsic) · Resiliency · Mood · Anxiety · Aspirations · Perseverance / determination · Sense of humour · Self-control · Social skills · Empathy | AK36: Within-Child — Behavioural Factors · Ability to develop and maintain friendships and relationships · Positive achievements · Care/concern for others, volunteering, helping · Dangerous or risk-taking behaviour · Verbal / physical abuse · Self-harm · Bullying · Truancy
